<?xml version="1.0" encoding="utf-8"?>
<!-- =================================================================================== -->
<!-- |    This document was autogenerated by xacro from tiptap_xacro.xml               | -->
<!-- |    EDITING THIS FILE BY HAND IS NOT RECOMMENDED                                 | -->
<!-- =================================================================================== -->
<robot name="tiptap" xmlns:xacro="http://www.ros.org/wiki/xacro">
  <!-- Command to generate the urdf: "rosrun xacro xacro tiptap_xacro.xml > tiptap.urdf" -->
  <!-- ################################## -->
  <!-- #### macros and definitions: ##### -->
  <!-- ################################## -->
  <material name="red">
    <color rgba="1 0 0 1"/>
  </material>
  <material name="black">
    <color rgba="0.1 0.1 0.1 1"/>
  </material>
  <material name="blue">
    <color rgba="0.1 0.1 0.8 1"/>
  </material>
  <link name="torso">
    <visual>
      <geometry>
        <box size="0.067 0.023 0.128"/>
      </geometry>
      <origin rpy="0 0 0" xyz="0 0 0"/>
      <material name="red"/>
    </visual>
    <collision>
      <geometry>
        <box size="0.0402 0.0138 0.0768"/>
      </geometry>
      <origin rpy="0 0 0" xyz="0 0 0"/>
      <!-- <contact_coefficients mu="0.08" /> -->
    </collision>
    <inertial>
      <origin rpy="1.57079632679 0 0" xyz="0 0 0"/>
      <mass value="0.1556"/>
      <inertia ixx="0.000219305233333" ixy="0.0" ixz="0.0" iyy="0.000270653233333" iyz="0.0" izz="6.50667333333e-05"/>
    </inertial>
  </link>
  <link name="hip_right">
    <visual>
      <geometry>
        <box size="0.047 0.047 0.094"/>
      </geometry>
      <origin rpy="0 0 0" xyz="0 0 0.047"/>
      <material name="red"/>
    </visual>
    <collision>
      <geometry>
        <box size="0.0282 0.0282 0.0564"/>
      </geometry>
      <origin rpy="0 0 0" xyz="0 0 0.047"/>
      <!-- <contact_coefficients mu="0.08" /> -->
    </collision>
    <inertial>
      <origin rpy="0 0 0" xyz="0 0 0.047"/>
      <mass value="0.1945"/>
      <inertia ixx="0.000179021041667" ixy="0.0" ixz="0.0" iyy="0.000179021041667" iyz="0.0" izz="7.16084166667e-05"/>
    </inertial>
  </link>
  <link name="hip_left">
    <visual>
      <geometry>
        <box size="0.047 0.047 0.094"/>
      </geometry>
      <origin rpy="0 0 0" xyz="0 0 0.047"/>
      <material name="blue"/>
    </visual>
    <collision>
      <geometry>
        <box size="0.0282 0.0282 0.0564"/>
      </geometry>
      <origin rpy="0 0 0" xyz="0 0 0.047"/>
      <!-- <contact_coefficients mu="0.08" /> -->
    </collision>
    <inertial>
      <origin rpy="0 0 0" xyz="0 0 0.047"/>
      <mass value="0.1945"/>
      <inertia ixx="0.000179021041667" ixy="0.0" ixz="0.0" iyy="0.000179021041667" iyz="0.0" izz="7.16084166667e-05"/>
    </inertial>
  </link>
  <link name="upper_leg_right">
    <visual>
      <geometry>
        <box size="0.026 0.022 0.123"/>
      </geometry>
      <origin rpy="0 0 0" xyz="0 0 -0.0615"/>
      <material name="red"/>
    </visual>
    <collision>
      <geometry>
        <box size="0.0156 0.0132 0.0738"/>
      </geometry>
      <origin rpy="0 0 0" xyz="0 0 -0.0615"/>
      <!-- <contact_coefficients mu="0.08" /> -->
    </collision>
    <inertial>
      <origin rpy="0 0 0" xyz="0 0 -0.0615"/>
      <mass value="0.05835"/>
      <inertia ixx="7.59182125e-05" ixy="0.0" ixz="0.0" iyy="7.68518125e-05" iyz="0.0" izz="5.6405e-06"/>
    </inertial>
  </link>
  <link name="upper_leg_left">
    <visual>
      <geometry>
        <box size="0.026 0.022 0.123"/>
      </geometry>
      <origin rpy="0 0 0" xyz="0 0 -0.0615"/>
      <material name="blue"/>
    </visual>
    <collision>
      <geometry>
        <box size="0.0156 0.0132 0.0738"/>
      </geometry>
      <origin rpy="0 0 0" xyz="0 0 -0.0615"/>
      <!-- <contact_coefficients mu="0.08" /> -->
    </collision>
    <inertial>
      <origin rpy="0 0 0" xyz="0 0 -0.0615"/>
      <mass value="0.05835"/>
      <inertia ixx="7.59182125e-05" ixy="0.0" ixz="0.0" iyy="7.68518125e-05" iyz="0.0" izz="5.6405e-06"/>
    </inertial>
  </link>
  <link name="lower_leg_right">
    <visual>
      <geometry>
        <box size="0.016 0.019 0.136"/>
      </geometry>
      <origin rpy="0 0 0" xyz="0 0 -0.068"/>
      <material name="red"/>
    </visual>
    <collision>
      <geometry>
        <box size="0.0096 0.0114 0.0816"/>
      </geometry>
      <origin rpy="0 0 0" xyz="0 0 -0.068"/>
      <!-- <contact_coefficients mu="0.08" /> -->
    </collision>
    <inertial>
      <origin rpy="0 0 0" xyz="0 0 -0.068"/>
      <mass value="0.05835"/>
      <inertia ixx="9.16921625e-05" ixy="0.0" ixz="0.0" iyy="9.11816e-05" iyz="0.0" izz="3.0001625e-06"/>
    </inertial>
  </link>
  <link name="lower_leg_left">
    <visual>
      <geometry>
        <box size="0.016 0.019 0.136"/>
      </geometry>
      <origin rpy="0 0 0" xyz="0 0 -0.068"/>
      <material name="blue"/>
    </visual>
    <collision>
      <geometry>
        <box size="0.0096 0.0114 0.0816"/>
      </geometry>
      <origin rpy="0 0 0" xyz="0 0 -0.068"/>
      <!-- <contact_coefficients mu="0.08" /> -->
    </collision>
    <inertial>
      <origin rpy="0 0 0" xyz="0 0 -0.068"/>
      <mass value="0.05835"/>
      <inertia ixx="9.16921625e-05" ixy="0.0" ixz="0.0" iyy="9.11816e-05" iyz="0.0" izz="3.0001625e-06"/>
    </inertial>
  </link>
  <link name="right_foot">
    <visual>
      <geometry>
        <sphere radius="0.0152"/>
      </geometry>
      <material name="black"/>
    </visual>
    <collision>
      <geometry>
        <sphere radius="0.0152"/>
      </geometry>
      <!-- <contact_coefficients mu="0.08" /> -->
    </collision>
    <inertial>
      <origin rpy="0 0 0" xyz="0 0 0"/>
      <mass value="0"/>
      <inertia ixx="1.0" ixy="0.0" ixz="0.0" iyy="1.0" iyz="0.0" izz="1.0"/>
    </inertial>
  </link>
  <link name="left_foot">
    <visual>
      <geometry>
        <sphere radius="0.0152"/>
      </geometry>
      <material name="black"/>
    </visual>
    <collision>
      <geometry>
        <sphere radius="0.0152"/>
      </geometry>
      <!-- <contact_coefficients mu="0.08" /> -->
    </collision>
    <inertial>
      <origin rpy="0 0 0" xyz="0 0 0"/>
      <mass value="0"/>
      <inertia ixx="1.0" ixy="0.0" ixz="0.0" iyy="1.0" iyz="0.0" izz="1.0"/>
    </inertial>
  </link>
  <!-- ############################### -->
  <!-- ############ joints: ########### -->
  <!-- ############################### -->
  <joint name="RightServo" type="revolute">
    <parent link="torso"/>
    <child link="hip_right"/>
    <axis xyz="0 1 0"/>
    <origin rpy="0 0.0 0" xyz="0.0382 0.0385 -0.047"/>
    <dynamics damping="0.01" friction="0.01"/>
    <limit effort="100" lower="-0.305432619099" upper="0.343829862643" velocity="100"/>
  </joint>
  <joint name="RightHip" type="revolute">
    <parent link="hip_right"/>
    <child link="upper_leg_right"/>
    <axis xyz="1 0 0"/>
    <origin rpy="0.0 0 0" xyz="0.0365 0 0.0235"/>
    <dynamics damping="0.01" friction="0.01"/>
    <limit effort="100" lower="-2.09439510239" upper="2.09439510239" velocity="100"/>
  </joint>
  <joint name="RightKnee" type="revolute">
    <parent link="upper_leg_right"/>
    <child link="lower_leg_right"/>
    <axis xyz="1 0 0"/>
    <origin rpy="0.0 0 0" xyz="0 0 -0.123"/>
    <dynamics damping="0.01" friction="0.01"/>
    <limit effort="100" lower="-2.09439510239" upper="2.09439510239" velocity="100"/>
  </joint>
  <joint name="LeftServo" type="revolute">
    <parent link="torso"/>
    <child link="hip_left"/>
    <axis xyz="0 1 0"/>
    <origin rpy="0 0.0 0" xyz="-0.0288 0.0385 -0.047"/>
    <dynamics damping="0.01" friction="0.01"/>
    <limit effort="100" lower="-0.305432619099" upper="0.343829862643" velocity="100"/>
  </joint>
  <joint name="LeftHip" type="revolute">
    <parent link="hip_left"/>
    <child link="upper_leg_left"/>
    <axis xyz="1 0 0"/>
    <origin rpy="0.0 0 0" xyz="-0.0365 0 0.0235"/>
    <dynamics damping="0.01" friction="0.01"/>
    <limit effort="100" lower="-2.09439510239" upper="2.09439510239" velocity="100"/>
  </joint>
  <joint name="LeftKnee" type="revolute">
    <parent link="upper_leg_left"/>
    <child link="lower_leg_left"/>
    <axis xyz="1 0 0"/>
    <origin rpy="0.0 0 0" xyz="0 0 -0.123"/>
    <dynamics damping="0.01" friction="0.01"/>
    <limit effort="100" lower="-2.09439510239" upper="2.09439510239" velocity="100"/>
  </joint>
  <joint name="LeftFoot" type="fixed">
    <parent link="lower_leg_left"/>
    <child link="left_foot"/>
    <origin rpy="0 0 0" xyz="0 0 -0.136"/>
  </joint>
  <joint name="RightFoot" type="fixed">
    <parent link="lower_leg_right"/>
    <child link="right_foot"/>
    <origin rpy="0 0 0" xyz="0 0 -0.136"/>
  </joint>
</robot>

